"use strict";(self.webpackChunkmy_website=self.webpackChunkmy_website||[]).push([[6729],{9729:(e,n,r)=>{r.r(n),r.d(n,{assets:()=>l,contentTitle:()=>i,default:()=>p,frontMatter:()=>a,metadata:()=>c,toc:()=>t});var o=r(4848),s=r(8453);const a={sidebar_label:"Tema 7: Errores y Excepciones",sidebar_position:7},i="Errores y Excepciones",c={id:"Apuntes python/Tema 7",title:"Errores y Excepciones",description:"Tabla de Contenidos",source:"@site/i18n/es/docusaurus-plugin-content-docs/current/Apuntes python/Tema 7.md",sourceDirName:"Apuntes python",slug:"/Apuntes python/Tema 7",permalink:"/apuntes-AOIngles/es/docs/Apuntes python/Tema 7",draft:!1,unlisted:!1,editUrl:"https://github.com/facebook/docusaurus/tree/main/packages/create-docusaurus/templates/shared/docs/Apuntes python/Tema 7.md",tags:[],version:"current",sidebarPosition:7,frontMatter:{sidebar_label:"Tema 7: Errores y Excepciones",sidebar_position:7},sidebar:"tutorialSidebar",previous:{title:"Tema 6: Funciones",permalink:"/apuntes-AOIngles/es/docs/Apuntes python/Tema 6"},next:{title:"Tema 8: Trabajo con Archivos",permalink:"/apuntes-AOIngles/es/docs/Apuntes python/Tema 8"}},l={},t=[{value:"Tabla de Contenidos",id:"tabla-de-contenidos",level:2},{value:"\xbfQu\xe9 es el Manejo de Excepciones en Python?",id:"qu\xe9-es-el-manejo-de-excepciones-en-python",level:2},{value:"Error cl\xe1sico del int\xe9rprete de Python",id:"error-cl\xe1sico-del-int\xe9rprete-de-python",level:3},{value:"Error personalizado",id:"error-personalizado",level:3},{value:"El Bloque <code>try</code>/<code>except</code>",id:"el-bloque-tryexcept",level:2},{value:"Ejemplo:",id:"ejemplo",level:4},{value:"<code>except</code>",id:"except",level:3},{value:"<code>except</code> para un Error Espec\xedfico",id:"except-para-un-error-espec\xedfico",level:3},{value:"<code>except</code> para Cualquier Error",id:"except-para-cualquier-error",level:3},{value:"<code>finally</code>",id:"finally",level:3},{value:"Lanzar un Error",id:"lanzar-un-error",level:2}];function d(e){const n={a:"a",code:"code",h1:"h1",h2:"h2",h3:"h3",h4:"h4",hr:"hr",img:"img",li:"li",p:"p",pre:"pre",strong:"strong",ul:"ul",...(0,s.R)(),...e.components};return(0,o.jsxs)(o.Fragment,{children:[(0,o.jsx)(n.h1,{id:"errores-y-excepciones",children:"Errores y Excepciones"}),"\n",(0,o.jsx)(n.h2,{id:"tabla-de-contenidos",children:"Tabla de Contenidos"}),"\n",(0,o.jsxs)(n.ul,{children:["\n",(0,o.jsx)(n.li,{children:(0,o.jsx)(n.a,{href:"#qu%C3%A9-es-el-manejo-de-excepciones-en-python",children:"\xbfQu\xe9 es el Manejo de Excepciones en Python?"})}),"\n",(0,o.jsx)(n.li,{children:(0,o.jsxs)(n.a,{href:"#el-bloque-tryexcept",children:["El Bloque ",(0,o.jsx)(n.code,{children:"try"}),"/",(0,o.jsx)(n.code,{children:"except"})]})}),"\n",(0,o.jsx)(n.li,{children:(0,o.jsx)(n.a,{href:"#lanzar-un-error",children:"Lanzar un Error"})}),"\n"]}),"\n",(0,o.jsx)(n.hr,{}),"\n",(0,o.jsx)(n.h2,{id:"qu\xe9-es-el-manejo-de-excepciones-en-python",children:"\xbfQu\xe9 es el Manejo de Excepciones en Python?"}),"\n",(0,o.jsxs)(n.p,{children:["Gestionar errores nos permitir\xe1 ",(0,o.jsx)(n.strong,{children:"evitar que nuestro programa se detenga abruptamente"})," y nos dar\xe1 la capacidad de ",(0,o.jsx)(n.strong,{children:"mostrar un error personalizado al usuario en lugar de los errores cl\xe1sicos del int\xe9rprete"}),"."]}),"\n",(0,o.jsx)(n.h3,{id:"error-cl\xe1sico-del-int\xe9rprete-de-python",children:"Error cl\xe1sico del int\xe9rprete de Python"}),"\n",(0,o.jsx)(n.pre,{children:(0,o.jsx)(n.code,{className:"language-python",children:"print(10/0)\n"})}),"\n",(0,o.jsx)(n.p,{children:(0,o.jsx)(n.strong,{children:"Consola:"})}),"\n",(0,o.jsx)(n.pre,{children:(0,o.jsx)(n.code,{className:"language-python",children:'Traceback (most recent call last):\r\n  File "<stdin>", line 1, in <module>\r\nZeroDivisionError: division by zero\n'})}),"\n",(0,o.jsx)(n.h3,{id:"error-personalizado",children:"Error personalizado"}),"\n",(0,o.jsx)(n.pre,{children:(0,o.jsx)(n.code,{className:"language-python",children:'try:\r\n    print(10/0)\r\n    \r\nexcept ZeroDivisionError:\r\n    print("You can\'t divide by zero!")\n'})}),"\n",(0,o.jsx)(n.p,{children:(0,o.jsx)(n.strong,{children:"Consola:"})}),"\n",(0,o.jsx)(n.pre,{children:(0,o.jsx)(n.code,{className:"language-console",children:"You can't divide by zero!\n"})}),"\n",(0,o.jsx)(n.hr,{}),"\n",(0,o.jsxs)(n.h2,{id:"el-bloque-tryexcept",children:["El Bloque ",(0,o.jsx)(n.code,{children:"try"}),"/",(0,o.jsx)(n.code,{children:"except"})]}),"\n",(0,o.jsxs)(n.p,{children:["Al usar ",(0,o.jsx)(n.code,{children:"try"}),"/",(0,o.jsx)(n.code,{children:"except"}),", podemos establecer una condici\xf3n para manejar errores dentro del bloque ",(0,o.jsx)(n.code,{children:"try"}),". Si ocurre un error, se ejecuta el c\xf3digo dentro del bloque ",(0,o.jsx)(n.code,{children:"except"}),". Si no ocurre ning\xfan error, el c\xf3digo se ejecuta normalmente."]}),"\n",(0,o.jsx)(n.h4,{id:"ejemplo",children:"Ejemplo:"}),"\n",(0,o.jsx)(n.pre,{children:(0,o.jsx)(n.code,{className:"language-python",children:'try:\r\n    # Example: Trying to add a text string with a number\r\n    result = "3" + 5\r\n    \r\nexcept TypeError:\r\n    print("You can\'t add a string with a number!")\n'})}),"\n",(0,o.jsx)(n.p,{children:(0,o.jsx)(n.strong,{children:"Consola:"})}),"\n",(0,o.jsx)(n.pre,{children:(0,o.jsx)(n.code,{className:"language-console",children:"You can't add a string with a number!\n"})}),"\n",(0,o.jsx)(n.h3,{id:"except",children:(0,o.jsx)(n.code,{children:"except"})}),"\n",(0,o.jsxs)(n.p,{children:["Podemos tener un ",(0,o.jsx)(n.code,{children:"except"})," general para cualquier error o m\xfaltiples bloques ",(0,o.jsx)(n.code,{children:"except"})," para errores espec\xedficos, lo que nos permite anticipar y manejar cada error de manera \xfanica."]}),"\n",(0,o.jsx)(n.p,{children:(0,o.jsx)(n.img,{alt:"try except example",src:r(701).A+"",width:"679",height:"240"})}),"\n",(0,o.jsxs)(n.h3,{id:"except-para-un-error-espec\xedfico",children:[(0,o.jsx)(n.code,{children:"except"})," para un Error Espec\xedfico"]}),"\n",(0,o.jsx)(n.p,{children:"Vamos a capturar un error particular, por ejemplo, el error que ocurre al intentar acceder a un \xedndice fuera del rango de una lista. Primero, veamos el error que aparece en el compilador al hacerlo:"}),"\n",(0,o.jsx)(n.pre,{children:(0,o.jsx)(n.code,{className:"language-python",children:'# Example: Accessing an index outside the range of a list\r\n#Index:  0      1      2\r\nlist = ["Hi", "Bye", False]\r\nitem = list[5]\n'})}),"\n",(0,o.jsx)(n.p,{children:(0,o.jsx)(n.strong,{children:"Consola:"})}),"\n",(0,o.jsx)(n.pre,{children:(0,o.jsx)(n.code,{className:"language-console",children:'Traceback (most recent call last):\r\n  File "<stdin>", line 3, in <module>\r\nIndexError: list index out of range\n'})}),"\n",(0,o.jsxs)(n.p,{children:["El ",(0,o.jsx)(n.strong,{children:"traceback proporciona informaci\xf3n sobre el error"}),", indicando d\xf3nde ocurri\xf3, lo que nos ayuda a entender y solucionar el problema."]}),"\n",(0,o.jsxs)(n.p,{children:["Indica que estamos intentando acceder a un elemento en la lista que est\xe1 ",(0,o.jsx)(n.strong,{children:"fuera del rango"}),", ya que nuestra lista solo tiene los \xedndices 0, 1 y 2, y estamos ",(0,o.jsx)(n.strong,{children:"intentando acceder al elemento en el \xedndice 5, que no existe"}),"."]}),"\n",(0,o.jsxs)(n.p,{children:["El tipo de error que da es ",(0,o.jsx)(n.code,{children:"IndexError"}),", ahora se ",(0,o.jsx)(n.strong,{children:"utilizar\xe1 un except espec\xedfico para ese tipo de error"}),", y ",(0,o.jsx)(n.strong,{children:"otro bloque except"})," al final ",(0,o.jsx)(n.strong,{children:"para cualquier otro error que pueda ocurrir"}),"."]}),"\n",(0,o.jsx)(n.pre,{children:(0,o.jsx)(n.code,{className:"language-python",children:'try:\r\n    #Index:  0      1      2\r\n    list = ["Hi", "Bye", False]\r\n    item = list[5]\r\n\r\nexcept IndexError: #Except for the specific error IndexError\r\n    print("You are trying to access a list index that is out of range")\r\nexcept: #Except for any other error\r\n    print("An error has occurred")\n'})}),"\n",(0,o.jsx)(n.p,{children:(0,o.jsx)(n.strong,{children:"Consola:"})}),"\n",(0,o.jsx)(n.pre,{children:(0,o.jsx)(n.code,{className:"language-console",children:"You are trying to access a list index that is out of range\n"})}),"\n",(0,o.jsxs)(n.h3,{id:"except-para-cualquier-error",children:[(0,o.jsx)(n.code,{children:"except"})," para Cualquier Error"]}),"\n",(0,o.jsxs)(n.p,{children:["Si usamos ",(0,o.jsx)(n.code,{children:"except"})," ",(0,o.jsx)(n.strong,{children:"sin a\xf1adir nada m\xe1s debajo"}),", significa que este except se aplicar\xe1 a ",(0,o.jsx)(n.strong,{children:"cualquier error que ocurra durante la ejecuci\xf3n del programa"}),"."]}),"\n",(0,o.jsx)(n.pre,{children:(0,o.jsx)(n.code,{className:"language-python",children:'try:\r\n    n1 = int(input("Enter an integer: "))\r\n    n2 = int(input("Enter another integer: "))\r\n    \r\n    div = n1/n2\r\n    print(f"{n1}/{n2} = {div}")\r\n    \r\nexcept: #Except for any error\r\n    print("An error has occurred")\n'})}),"\n",(0,o.jsxs)(n.p,{children:["\xbfCu\xe1l es el problema? En el ejemplo anterior ",(0,o.jsx)(n.strong,{children:"pueden ocurrir dos tipos de errores"}),":"]}),"\n",(0,o.jsxs)(n.ul,{children:["\n",(0,o.jsxs)(n.li,{children:[(0,o.jsx)(n.strong,{children:"Se ingresa un valor que no se puede convertir a entero"}),", por ejemplo, una letra, en ",(0,o.jsx)(n.code,{children:"n1"})," o ",(0,o.jsx)(n.code,{children:"n2"}),"."]}),"\n"]}),"\n",(0,o.jsx)(n.p,{children:(0,o.jsx)(n.strong,{children:"Consola:"})}),"\n",(0,o.jsx)(n.pre,{children:(0,o.jsx)(n.code,{className:"language-console",children:"Enter an integer: 32\r\nEnter another integer: hola\r\nAn error has occurred\n"})}),"\n",(0,o.jsxs)(n.ul,{children:["\n",(0,o.jsxs)(n.li,{children:["Se ",(0,o.jsxs)(n.strong,{children:["ingresa el n\xfamero 0 en ",(0,o.jsx)(n.code,{children:"n2"})]}),", lo cual no dar\xeda un error al convertirlo a int, pero dar\xe1 un error al realizar la divisi\xf3n, ya que no se puede dividir por 0."]}),"\n"]}),"\n",(0,o.jsx)(n.p,{children:(0,o.jsx)(n.strong,{children:"Consola:"})}),"\n",(0,o.jsx)(n.pre,{children:(0,o.jsx)(n.code,{className:"language-console",children:"Enter an integer: 24\r\nEnter another integer: 0\r\nAn error has occurred\n"})}),"\n",(0,o.jsxs)(n.p,{children:["Si ponemos un except general, nos avisar\xe1 que hay un error, pero no sabremos qu\xe9 est\xe1 fallando. Para hacer nuestro programa m\xe1s eficiente, ",(0,o.jsx)(n.strong,{children:"lo mejor ser\xeda a\xf1adir un tipo de error espec\xedfico para poder diferenciar entre los errores que puedan ocurrir"}),"."]}),"\n",(0,o.jsx)(n.pre,{children:(0,o.jsx)(n.code,{className:"language-python",children:'try:\r\n    n1 = int(input("Enter an integer: "))\r\n    n2 = int(input("Enter another integer: "))\r\n    \r\n    div = n1/n2\r\n    print(f"{n1}/{n2} = {div}")\r\n    \r\nexcept ZeroDivisionError: #Except for when the value of n2 is 0\r\n    print("You are trying to divide by zero")\r\nexcept ValueError: #Except when a value that cannot be converted to int is entered into n1 or n2\r\n    print("You have entered a value that cannot be converted to an integer")\r\nexcept: #Except for any other error\r\n    print("An error has occurred")\n'})}),"\n",(0,o.jsxs)(n.ul,{children:["\n",(0,o.jsxs)(n.li,{children:["Ahora, cuando se ingresa un valor que no se puede convertir a int en ",(0,o.jsx)(n.code,{children:"n1"})," o ",(0,o.jsx)(n.code,{children:"n2"}),":"]}),"\n"]}),"\n",(0,o.jsx)(n.p,{children:(0,o.jsx)(n.strong,{children:"Consola:"})}),"\n",(0,o.jsx)(n.pre,{children:(0,o.jsx)(n.code,{className:"language-console",children:"Enter an integer: 32\r\nEnter another integer: hola\r\nYou have entered a value that cannot be converted to an integer:\n"})}),"\n",(0,o.jsxs)(n.ul,{children:["\n",(0,o.jsxs)(n.li,{children:["Cuando el valor de ",(0,o.jsx)(n.code,{children:"n2"})," es 0:"]}),"\n"]}),"\n",(0,o.jsx)(n.p,{children:(0,o.jsx)(n.strong,{children:"Consola:"})}),"\n",(0,o.jsx)(n.pre,{children:(0,o.jsx)(n.code,{className:"language-console",children:"Enter an integer: 24\r\nEnter another integer: 0\r\nYou are trying to divide by zero\n"})}),"\n",(0,o.jsxs)(n.ul,{children:["\n",(0,o.jsx)(n.li,{children:"Cuando no hay ning\xfan error:"}),"\n"]}),"\n",(0,o.jsx)(n.p,{children:(0,o.jsx)(n.strong,{children:"Consola:"})}),"\n",(0,o.jsx)(n.pre,{children:(0,o.jsx)(n.code,{className:"language-console",children:"Enter an integer: 40\r\nEnter another integer: 10\r\n40/10 = 4.0\n"})}),"\n",(0,o.jsx)(n.h3,{id:"finally",children:(0,o.jsx)(n.code,{children:"finally"})}),"\n",(0,o.jsxs)(n.p,{children:["El bloque ",(0,o.jsx)(n.code,{children:"finally"})," nos permite ejecutar c\xf3digo sin importar si ocurri\xf3 un error o no. No es necesario tener un bloque ",(0,o.jsx)(n.code,{children:"except"})," si tenemos un ",(0,o.jsx)(n.code,{children:"finally"}),"."]}),"\n",(0,o.jsx)(n.p,{children:(0,o.jsx)(n.img,{alt:"finally example",src:r(5125).A+"",width:"353",height:"506"})}),"\n",(0,o.jsxs)(n.p,{children:["En el siguiente ejemplo vamos a intentar acceder a una clave de un diccionario que no existe, lo que nos dar\xe1 un error de tipo ",(0,o.jsx)(n.code,{children:"KeyError"}),", el ",(0,o.jsx)(n.code,{children:"finally"})," se ejecutar\xe1 despu\xe9s del ",(0,o.jsx)(n.code,{children:"except"}),"."]}),"\n",(0,o.jsx)(n.pre,{children:(0,o.jsx)(n.code,{className:"language-python",children:"try:\r\n    # Example: Trying to access a non-existent key in a dictionary\r\n    dictionary = {'name': 'John', 'age': 30}\r\n    value = dictionary['height']\r\nexcept KeyError:\r\n    print(\"You are trying to access a non-existent key in a dictionary!\")\r\nfinally:\r\n    print(\"This will execute no matter what\")\n"})}),"\n",(0,o.jsx)(n.p,{children:(0,o.jsx)(n.strong,{children:"Consola:"})}),"\n",(0,o.jsx)(n.pre,{children:(0,o.jsx)(n.code,{className:"language-console",children:"You are trying to access a non-existent key in a dictionary!\r\nThis will execute no matter what.\n"})}),"\n",(0,o.jsxs)(n.p,{children:[(0,o.jsxs)(n.strong,{children:["El ",(0,o.jsx)(n.code,{children:"finally"})," siempre se ejecuta"]}),", sin importar si ocurri\xf3 un error o no, Ahora bien, en el ejemplo siguiente no se produce ning\xfan error ya que estamos accediendo a una clave que existe en el diccionario; el ",(0,o.jsx)(n.code,{children:"finally"})," se ejecuta de todos modos."]}),"\n",(0,o.jsx)(n.pre,{children:(0,o.jsx)(n.code,{className:"language-python",children:"try:\r\n    # Example: Trying to access a existent key in a dictionary\r\n    dictionary = {'name': 'John', 'age': 30}\r\n    value = dictionary['age']\r\nexcept KeyError:\r\n    print(\"You are trying to access a non-existent key in a dictionary!\")\r\nfinally:\r\n    print(\"This will execute no matter what\")\n"})}),"\n",(0,o.jsx)(n.p,{children:(0,o.jsx)(n.strong,{children:"Consola:"})}),"\n",(0,o.jsx)(n.pre,{children:(0,o.jsx)(n.code,{className:"language-console",children:"30\r\nThis will execute no matter what\n"})}),"\n",(0,o.jsx)(n.hr,{}),"\n",(0,o.jsx)(n.h2,{id:"lanzar-un-error",children:"Lanzar un Error"}),"\n",(0,o.jsxs)(n.p,{children:["A veces necesitamos disparar manualmente un error utilizando la palabra clave ",(0,o.jsx)(n.code,{children:"raise"}),". Esto nos permite crear errores personalizados y manejarlos con ",(0,o.jsx)(n.code,{children:"except"}),"."]}),"\n",(0,o.jsx)(n.pre,{children:(0,o.jsx)(n.code,{className:"language-python",children:'def check_letter(word):\r\n    if \'\xf1\' in word:\r\n        raise ValueError("Word contains forbidden character: \xf1")\r\n    return word\r\n\r\ntry:\r\n    check_letter("ni\xf1o")\r\nexcept ValueError as e:\r\n    print(f"Error: {e}")\n'})}),"\n",(0,o.jsx)(n.p,{children:(0,o.jsx)(n.strong,{children:"Consola:"})}),"\n",(0,o.jsx)(n.pre,{children:(0,o.jsx)(n.code,{className:"language-console",children:"Error: Word contains forbidden character: \xf1\n"})}),"\n",(0,o.jsxs)(n.p,{children:["En este ejemplo, se lanza un ",(0,o.jsx)(n.code,{children:"ValueError"})," si la palabra contiene el car\xe1cter '\xf1', y el error se maneja con el bloque ",(0,o.jsx)(n.code,{children:"except"}),"."]})]})}function p(e={}){const{wrapper:n}={...(0,s.R)(),...e.components};return n?(0,o.jsx)(n,{...e,children:(0,o.jsx)(d,{...e})}):d(e)}},5125:(e,n,r)=>{r.d(n,{A:()=>o});const o=r.p+"assets/images/finally-0a69d55ed3135dd9d6d548d80f8f962e.png"},701:(e,n,r)=>{r.d(n,{A:()=>o});const o=r.p+"assets/images/try-except-1ae05caf79303dce55e9f1224609b79f.png"},8453:(e,n,r)=>{r.d(n,{R:()=>i,x:()=>c});var o=r(6540);const s={},a=o.createContext(s);function i(e){const n=o.useContext(a);return o.useMemo((function(){return"function"==typeof e?e(n):{...n,...e}}),[n,e])}function c(e){let n;return n=e.disableParentContext?"function"==typeof e.components?e.components(s):e.components||s:i(e.components),o.createElement(a.Provider,{value:n},e.children)}}}]);